<sdf version='1.7'>
  <model name='axioma_v2'>

    <link name='base_link'>
      
      <inertial>
        <pose>0 0 0 0 -0 0</pose>
        <mass>1</mass>
        <inertia>
          <ixx>0.0227</ixx>
          <ixy>0</ixy>
          <ixz>0</ixz> 
          <iyy>0.0852</iyy>
          <iyz>0</iyz>
          <izz>0.1041</izz>
        </inertia>
      </inertial>
      <collision name='base_link_collision'>
        <pose>0 0 0 0 -0 0</pose>
        <geometry>
          <mesh>
            <scale>1 1 1</scale>
            <uri>model://axioma_v2/meshes/collision/chasis.dae</uri>
          </mesh>
        </geometry>
      </collision>
      <visual name='base_link_visual'>
        <pose>0 0 0 0 -0 0</pose>
        <geometry>
          <mesh>
            <scale>1 1 1</scale>
            <uri>model://axioma_v2/meshes/visual/chasis.stl</uri>
          </mesh>
        </geometry>
      </visual>
    </link>
    <joint name='base_to_wheel1' type='revolute'>
      <pose relative_to='base_link'>0.06442 0.07385 0.04068 3.141516 -0 3.141516</pose>
      <parent>base_link</parent>
      <child>wheel_1</child>
      <axis>
        <xyz>0 1 0</xyz>
        <limit>
          <lower>-1e+16</lower>
          <upper>1e+16</upper>
        </limit>
        <!--dynamics>
          <spring_reference>0</spring_reference>
          <spring_stiffness>0</spring_stiffness>
        </dynamics-->
      </axis>
    </joint>
    <link name='wheel_1'>
      <pose relative_to='base_to_wheel1'>0 0 0 0 -0 0</pose>
      <inertial>
        <pose>0 0 0 0 -0 0</pose>
        <mass>0.1</mass>
        <inertia>
          <ixx>0.0029</ixx>
          <ixy>0</ixy>
          <ixz>0</ixz>
          <iyy>0.0029</iyy>
          <iyz>0</iyz>
          <izz>0.0056</izz>
        </inertia>
      </inertial>
      <collision name='wheel_1_collision'>
        <pose>0 0.02 0 -1.5707 -0 0</pose>
        <geometry>
      
          <cylinder>
            <radius>0.0381</radius>
            <length>0.03</length>
          </cylinder>
      
        </geometry>
                <surface>
          <friction>
            <ode>
              <mu>1</mu>
              <mu2>1</mu2>
              <slip1>0</slip1>
              <slip2>0</slip2>
            </ode>
          </friction>
          <contact>
            <ode>
              <soft_cfm>0</soft_cfm>
              <soft_erp>0.2</soft_erp>
              <kp>1e+13</kp>
              <kd>1</kd>
              <max_vel>0.01</max_vel>
              <min_depth>0.01</min_depth>
            </ode>
          </contact>
        </surface>
      </collision>
      <visual name='wheel_1_visual'>
        <pose>0 0 0 0 -0 0</pose>
        <geometry>
          <mesh>
            <scale>1 1 1</scale>
            <uri>model://axioma_v2/meshes/visual/llanta.stl</uri>
          </mesh>
        </geometry>
          <material>
          <diffuse>0.5 0.5 0.5 1</diffuse>
          <ambient>0 0 0 1</ambient>
          <specular>1 1 1 1</specular>
          <emissive>0 0 0 1</emissive>
        </material>
      </visual>
    </link>
    <joint name='base_to_wheel2' type='revolute'>
      <pose relative_to='base_link'>-0.071224 0.07385 0.04068 3.141516 -0 3.141516</pose>
      <parent>base_link</parent>
      <child>wheel_2</child>
      <axis>
        <xyz>0 1 0</xyz>
        <limit>
          <lower>-1e+16</lower>
          <upper>1e+16</upper>
        </limit>
        <!--dynamics>
          <spring_reference>0</spring_reference>
          <spring_stiffness>0</spring_stiffness>
        </dynamics-->
      </axis>
    </joint>
    <link name='wheel_2'>
      <pose relative_to='base_to_wheel2'>0 0 0 0 -0 0</pose>
      <inertial>
        <pose>0 0 0 0 -0 0</pose>
        <mass>0.1</mass>
        <inertia>
          <ixx>0.0029</ixx>
          <ixy>0</ixy>
          <ixz>0</ixz>
          <iyy>0.0029</iyy>
          <iyz>0</iyz>
          <izz>0.0056</izz>
        </inertia>
      </inertial>
      <collision name='wheel_2_collision'>
        <pose>0 0.02 0 -1.5707 -0 0</pose>
        <geometry>
      
          <cylinder>
            <radius>0.0381</radius>
            <length>0.03</length>
          </cylinder>
      
        </geometry>
                <surface>
          <friction>
            <ode>
              <mu>1</mu>
              <mu2>1</mu2>
              <slip1>0</slip1>
              <slip2>0</slip2>
            </ode>
          </friction>
          <contact>
            <ode>
              <soft_cfm>0</soft_cfm>
              <soft_erp>0.2</soft_erp>
              <kp>1e+13</kp>
              <kd>1</kd>
              <max_vel>0.01</max_vel>
              <min_depth>0.01</min_depth>
            </ode>
          </contact>
        </surface>
      </collision>
      <visual name='wheel_2_visual'>
        <pose>0 0 0 0 -0 0</pose>
        <geometry>
          <mesh>
            <scale>1 1 1</scale>
            <uri>model://axioma_v2/meshes/visual/llanta.stl</uri>
          </mesh>
        </geometry>
          <material>
          <diffuse>0.5 0.5 0.5 1</diffuse>
          <ambient>0 0 0 1</ambient>
          <specular>1 1 1 1</specular>
          <emissive>0 0 0 1</emissive>
        </material>
      </visual>
    </link>
    <joint name='base_to_wheel3' type='revolute'>
      <pose relative_to='base_link'>-0.071224 -0.0625 0.04068 0 0 3.141592</pose>
      <parent>base_link</parent>
      <child>wheel_3</child>
      <axis>
        <xyz>0 -1 0</xyz>
        <limit>
          <lower>-1e+16</lower>
          <upper>1e+16</upper>
        </limit>
        <!--dynamics>
          <spring_reference>0</spring_reference>
          <spring_stiffness>0</spring_stiffness>
        </dynamics-->
      </axis>
    </joint>
    <link name='wheel_3'>
      <pose relative_to='base_to_wheel3'>0 0 0 0 -0 0</pose>
      <inertial>
        <pose>0 0 0 0 -0 0</pose>
        <mass>0.1</mass>
        <inertia>
          <ixx>0.0029</ixx>
          <ixy>0</ixy>
          <ixz>0</ixz>
          <iyy>0.0029</iyy>
          <iyz>0</iyz>
          <izz>0.0056</izz>
        </inertia>
      </inertial>
      <collision name='wheel_3_collision'>
        <pose>0 0.02 0 -1.5707 -0 0</pose>
        <geometry>
      
          <cylinder>
            <radius>0.0381</radius>
            <length>0.03</length>
          </cylinder>
      
        </geometry>
                <surface>
          <friction>
            <ode>
              <mu>1</mu>
              <mu2>1</mu2>
              <slip1>0</slip1>
              <slip2>0</slip2>
            </ode>
          </friction>
          <contact>
            <ode>
              <soft_cfm>0</soft_cfm>
              <soft_erp>0.2</soft_erp>
              <kp>1e+13</kp>
              <kd>1</kd>
              <max_vel>0.01</max_vel>
              <min_depth>0.01</min_depth>
            </ode>
          </contact>
        </surface>
      </collision>
      <visual name='wheel_3_visual'>
        <pose>0 0 0 0 -0 0</pose>
        <geometry>
          <mesh>
            <scale>1 1 1</scale>
            <uri>model://axioma_v2/meshes/visual/llanta.stl</uri>
          </mesh>
        </geometry>
                <material>
          <diffuse>0.5 0.5 0.5 1</diffuse>
          <ambient>0 0 0 1</ambient>
          <specular>1 1 1 1</specular>
          <emissive>0 0 0 1</emissive>
        </material>
      </visual>
    </link>
    <joint name='base_to_wheel4' type='revolute'>
      <pose relative_to='base_link'>0.064423 -0.0625 0.04068 0 0 3.141592</pose>
      <parent>base_link</parent>
      <child>wheel_4</child>
      <axis>
        <xyz>0 -1 0</xyz>
        <limit>
          <lower>-1e+16</lower>
          <upper>1e+16</upper>
        </limit>
        <!--dynamics>
          <spring_reference>0</spring_reference>
          <spring_stiffness>0</spring_stiffness>
        </dynamics-->
      </axis>
    </joint>
    <link name='wheel_4'>
      <pose relative_to='base_to_wheel4'>0 0 0 0 -0 0</pose>
      <inertial>
        <pose>0 0 0 0 -0 0</pose>
        <mass>0.1</mass>
        <inertia>
          <ixx>0.0029</ixx>
          <ixy>0</ixy>
          <ixz>0</ixz>
          <iyy>0.0029</iyy>
          <iyz>0</iyz>
          <izz>0.0056</izz>
        </inertia>
      </inertial>
      <collision name='wheel_4_collision'>
        <pose>0 0.02 0 -1.5707 -0 0</pose>
        <geometry>
      
          <cylinder>
            <radius>0.0381</radius>
            <length>0.03</length>
          </cylinder>
      
        </geometry>
                <surface>
          <friction>
            <ode>
              <mu>1</mu>
              <mu2>1</mu2>
              <slip1>0</slip1>
              <slip2>0</slip2>
            </ode>
          </friction>
          <contact>
            <ode>
              <soft_cfm>0</soft_cfm>
              <soft_erp>0.2</soft_erp>
              <kp>1e+13</kp>
              <kd>1</kd>
              <max_vel>0.01</max_vel>
              <min_depth>0.01</min_depth>
            </ode>
          </contact>
        </surface>
      </collision>
      <visual name='wheel_4_visual'>
        <pose>0 0 0 0 -0 0</pose>
        <geometry>
          <mesh>
            <scale>1 1 1</scale>
            <uri>model://axioma_v2/meshes/visual/llanta.stl</uri>
          </mesh>
        </geometry>
                        <material>
          <diffuse>0.5 0.5 0.5 1</diffuse>
          <ambient>0 0 0 1</ambient>
          <specular>1 1 1 1</specular>
          <emissive>0 0 0 1</emissive>
        </material>
      </visual>
    </link>

   <link name="base_scan">
    <pose> 0 0 0.15 0 0 0</pose>
        <inertial> 
          <inertia>
            <ixx>0.001</ixx>
            <ixy>0.000</ixy>
            <ixz>0.000</ixz>
            <iyy>0.001</iyy>
            <iyz>0.000</iyz>
            <izz>0.001</izz>
          </inertia>
          <mass>0.125</mass>
        </inertial>
        <collision name="lidar_sensor_collision"> 
          <geometry>
            <cylinder>
              <radius>0.035</radius>
              <length>0.030</length>
            </cylinder>
          </geometry>
        </collision>
        <visual name="lidar_sensor_visual"> 
          <geometry>
            <cylinder>
              <radius>0.035</radius>
              <length>0.030</length>
            </cylinder>
          </geometry>
        </visual>
        <sensor name="hls_lfcd_lds" type="ray">
          <pose>0 0 0 0 0 0</pose>
          <always_on>true</always_on>
          <visualize>true</visualize> 
          <update_rate>20</update_rate>
          <ray>
            <scan>
              <horizontal>
                <samples>360</samples>
                <resolution>2.000000</resolution>
                <min_angle>0.000000</min_angle>
                <max_angle>6.280000</max_angle>
              </horizontal>
            </scan>
            <range>
              <min>0.120000</min>
              <max>3.5</max>
              <resolution>0.02000</resolution>
            </range>
            <!--noise>
              <type>gaussian</type>
              <mean>0.0</mean>
              <stddev>0.01</stddev>
            </noise-->
          </ray>
          <plugin name="laserscan" filename="libgazebo_ros_ray_sensor.so">
            <ros>
              <!--namespace>/axioma</namespace--> 
                <remapping>~/out:=scan</remapping>
            </ros>
            
            <output_type>sensor_msgs/LaserScan</output_type>
            <frame_name>base_link</frame_name> <!--TODO: cambiar al frame que coinicda en el urdf-->
          </plugin>  
        </sensor>
        <!--sensor name="intel_realsense_r200_depth" type="depth">
          <always_on>1</always_on>
          <update_rate>5</update_rate>
          <pose>0 0.4 0 -1.5708 0 0</pose>
          <camera name="realsense_depth_camera">
          </camera>
          <plugin name="intel_realsense_r200_depth_driver" filename="libgazebo_ros_camera.so">
            <ros>
            </ros>
            <camera_name>intel_realsense_r200_depth</camera_name>
            <frame_name>camera_depth_frame</frame_name>
            <hack_baseline>0.07</hack_baseline>
            <min_depth>0.001</min_depth>
            <max_depth>5.0</max_depth>
          </plugin>
        </sensor-->
      </link>

    <link name="imu_link">
        <pose > 0.1 0.1 0.12 0 0 0</pose>
        <sensor name="tb3_imu" type="imu">
          <always_on>true</always_on>
          <update_rate>50</update_rate>
          <imu>
            <angular_velocity>
              <x>
                <noise type="gaussian">
                  <mean>0.0</mean>
                  <stddev>2e-4</stddev>
                </noise>
              </x>
              <y>
                <noise type="gaussian">
                  <mean>0.0</mean>
                  <stddev>2e-4</stddev>
                </noise>
              </y>
              <z>
                <noise type="gaussian">
                  <mean>0.0</mean>
                  <stddev>2e-4</stddev>
                </noise>
              </z>
            </angular_velocity>
            <linear_acceleration>
              <x>
                <noise type="gaussian">
                  <mean>0.0</mean>
                  <stddev>1.7e-2</stddev>
                </noise>
              </x>
              <y>
                <noise type="gaussian">
                  <mean>0.0</mean>
                  <stddev>1.7e-2</stddev>
                </noise>
              </y>
              <z>
                <noise type="gaussian">
                  <mean>0.0</mean>
                  <stddev>1.7e-2</stddev>
                </noise>
              </z>
            </linear_acceleration>
          </imu>
          <plugin name="turtlebot3_imu" filename="libgazebo_ros_imu_sensor.so">
            <ros>
              <namespace>/axioma</namespace>
              <remapping>~/out:=imu</remapping>
            </ros>
          </plugin>
        </sensor>
      </link>
   
    <joint name="imu_joint" type="fixed">
        <parent>base_link</parent>
        <child>imu_link</child> 
        <axis>
          <xyz>0 0 0</xyz>
        </axis>
    </joint>



    <joint name="lidar_joint" type="fixed">
        <parent>base_link</parent>
        <child>base_scan</child> 
        <axis>
          <xyz>0 0 0</xyz>
        </axis>
    </joint>
    <plugin name='skid_steer_drive' filename='libgazebo_ros_diff_drive.so'>
        
        <!-- Update rate -->
        <update_rate>20</update_rate> 
        <!-- Number of wheel pairs -->
        <num_wheel_pairs>2</num_wheel_pairs> 
        <!-- wheels0 -->
        <left_joint>base_to_wheel1</left_joint>
        <right_joint>base_to_wheel4</right_joint> 
        <!-- wheels1-->
        <left_joint>base_to_wheel2</left_joint>
        <right_joint>base_to_wheel3</right_joint> 
        <!-- kinematics -->
        <wheel_separation>0.1725</wheel_separation>
        <wheel_separation>0.1725</wheel_separation> 
        <wheel_diameter>0.0762</wheel_diameter>
        <wheel_diameter>0.0762</wheel_diameter>         
        <!-- limits -->
        <max_wheel_torque>20</max_wheel_torque>
        <max_wheel_acceleration>1</max_wheel_acceleration> 
        <!-- output -->
        <publish_odom>true</publish_odom>
        <publish_odom_tf>true</publish_odom_tf>
        <odometry_frame>odom</odometry_frame>
        <robot_base_frame>base_link</robot_base_frame> 
      </plugin>
      
      <plugin name="scooby_joint_state" filename="libgazebo_ros_joint_state_publisher.so">
      <ros>
         <!--namespace>/snoopy</namespace--> 
        <remapping>~/out:=joint_states</remapping>
      </ros>
      <update_rate>20</update_rate>
      <joint_name>base_to_wheel1</joint_name> <!--motor direita-->
      <joint_name>base_to_wheel2</joint_name> <!--motor esquerda-->
      <joint_name>base_to_wheel3</joint_name>
      <joint_name>base_to_wheel4</joint_name>  
    </plugin>
  </model>
</sdf>
