<sdf version='1.7'>
  <model name='sam_bot'>
    <joint name='fixed' type='fixed'>
      <pose relative_to='__model__'>0 0 0 0 -0 0</pose>
      <parent>world</parent>
      <child>base_link</child>
    </joint>
    <link name='base_link'>
      <pose relative_to='fixed'>0 0 0 0 -0 0</pose>
      <inertial>
        <pose>0 0 0 0 -0 0</pose>
        <mass>100</mass>
        <inertia>
          <ixx>1</ixx>
          <ixy>0</ixy>
          <ixz>0</ixz>
          <iyy>1</iyy>
          <iyz>0</iyz>
          <izz>1</izz>
        </inertia>
      </inertial>
      <collision name='base_link_collision'>
        <pose>0 0 0 0 -0 0</pose>
        <geometry>
          <mesh>
            <scale>1 1 1</scale>
            <uri>model://axioma_urdf/meshes/collision/chasis.dae</uri>
          </mesh>
        </geometry>
      </collision>
      <visual name='base_link_visual'>
        <pose>0 0 0 0 -0 0</pose>
        <geometry>
          <mesh>
            <scale>1 1 1</scale>
            <uri>model://axioma_urdf/meshes/visual/chasis.stl</uri>
          </mesh>
        </geometry>
      </visual>
    </link>
    <joint name='base_to_wheel1' type='revolute'>
      <pose relative_to='base_link'>0.06442 0.07385 0.04068 0 -0 0</pose>
      <parent>base_link</parent>
      <child>wheel_1</child>
      <axis>
        <xyz>0 1 0</xyz>
        <limit>
          <lower>-1e+16</lower>
          <upper>1e+16</upper>
        </limit>
        <dynamics>
          <spring_reference>0</spring_reference>
          <spring_stiffness>0</spring_stiffness>
        </dynamics>
      </axis>
    </joint>
    <link name='wheel_1'>
      <pose relative_to='base_to_wheel1'>0 0 0 0 -0 0</pose>
      <inertial>
        <pose>0 0 0 0 -0 0</pose>
        <mass>10</mass>
        <inertia>
          <ixx>1</ixx>
          <ixy>0</ixy>
          <ixz>0</ixz>
          <iyy>1</iyy>
          <iyz>0</iyz>
          <izz>1</izz>
        </inertia>
      </inertial>
      <collision name='wheel_1_collision'>
        <pose>0 0 0 0 -0 0</pose>
        <geometry>
          <mesh>
            <scale>1 1 1</scale>
            <uri>model://axioma_urdf/meshes/collision/llanta.dae</uri>
          </mesh>
        </geometry>
      </collision>
      <visual name='wheel_1_visual'>
        <pose>0 0 0 0 -0 0</pose>
        <geometry>
          <mesh>
            <scale>1 1 1</scale>
            <uri>model://axioma_urdf/meshes/visual/llanta.stl</uri>
          </mesh>
        </geometry>
      </visual>
    </link>
    <joint name='base_to_wheel2' type='revolute'>
      <pose relative_to='base_link'>-0.071224 0.07385 0.04068 0 -0 0</pose>
      <parent>base_link</parent>
      <child>wheel_2</child>
      <axis>
        <xyz>0 1 0</xyz>
        <limit>
          <lower>-1e+16</lower>
          <upper>1e+16</upper>
        </limit>
        <dynamics>
          <spring_reference>0</spring_reference>
          <spring_stiffness>0</spring_stiffness>
        </dynamics>
      </axis>
    </joint>
    <link name='wheel_2'>
      <pose relative_to='base_to_wheel2'>0 0 0 0 -0 0</pose>
      <inertial>
        <pose>0 0 0 0 -0 0</pose>
        <mass>10</mass>
        <inertia>
          <ixx>1</ixx>
          <ixy>0</ixy>
          <ixz>0</ixz>
          <iyy>1</iyy>
          <iyz>0</iyz>
          <izz>1</izz>
        </inertia>
      </inertial>
      <collision name='wheel_2_collision'>
        <pose>0 0 0 0 -0 0</pose>
        <geometry>
          <mesh>
            <scale>1 1 1</scale>
            <uri>model://axioma_urdf/meshes/collision/llanta.dae</uri>
          </mesh>
        </geometry>
      </collision>
      <visual name='wheel_2_visual'>
        <pose>0 0 0 0 -0 0</pose>
        <geometry>
          <mesh>
            <scale>1 1 1</scale>
            <uri>model://axioma_urdf/meshes/visual/llanta.stl</uri>
          </mesh>
        </geometry>
      </visual>
    </link>
    <joint name='base_to_wheel3' type='revolute'>
      <pose relative_to='base_link'>-0.071224 -0.0625 0.04068 0 0 -3.14159</pose>
      <parent>base_link</parent>
      <child>wheel_3</child>
      <axis>
        <xyz>0 1 0</xyz>
        <limit>
          <lower>-1e+16</lower>
          <upper>1e+16</upper>
        </limit>
        <dynamics>
          <spring_reference>0</spring_reference>
          <spring_stiffness>0</spring_stiffness>
        </dynamics>
      </axis>
    </joint>
    <link name='wheel_3'>
      <pose relative_to='base_to_wheel3'>0 0 0 0 -0 0</pose>
      <inertial>
        <pose>0 0 0 0 -0 0</pose>
        <mass>10</mass>
        <inertia>
          <ixx>1</ixx>
          <ixy>0</ixy>
          <ixz>0</ixz>
          <iyy>1</iyy>
          <iyz>0</iyz>
          <izz>1</izz>
        </inertia>
      </inertial>
      <collision name='wheel_3_collision'>
        <pose>0 0 0 0 -0 0</pose>
        <geometry>
          <mesh>
            <scale>1 1 1</scale>
            <uri>model://axioma_urdf/meshes/collision/llanta.dae</uri>
          </mesh>
        </geometry>
      </collision>
      <visual name='wheel_3_visual'>
        <pose>0 0 0 0 -0 0</pose>
        <geometry>
          <mesh>
            <scale>1 1 1</scale>
            <uri>model://axioma_urdf/meshes/visual/llanta.stl</uri>
          </mesh>
        </geometry>
      </visual>
    </link>
    <joint name='base_to_wheel4' type='revolute'>
      <pose relative_to='base_link'>0.064423 -0.0625 0.04068 0 0 -3.14159</pose>
      <parent>base_link</parent>
      <child>wheel_4</child>
      <axis>
        <xyz>0 1 0</xyz>
        <limit>
          <lower>-1e+16</lower>
          <upper>1e+16</upper>
        </limit>
        <dynamics>
          <spring_reference>0</spring_reference>
          <spring_stiffness>0</spring_stiffness>
        </dynamics>
      </axis>
    </joint>
    <link name='wheel_4'>
      <pose relative_to='base_to_wheel4'>0 0 0 0 -0 0</pose>
      <inertial>
        <pose>0 0 0 0 -0 0</pose>
        <mass>10</mass>
        <inertia>
          <ixx>1</ixx>
          <ixy>0</ixy>
          <ixz>0</ixz>
          <iyy>1</iyy>
          <iyz>0</iyz>
          <izz>1</izz>
        </inertia>
      </inertial>
      <collision name='wheel_4_collision'>
        <pose>0 0 0 0 -0 0</pose>
        <geometry>
          <mesh>
            <scale>1 1 1</scale>
            <uri>model://axioma_urdf/meshes/collision/llanta.dae</uri>
          </mesh>
        </geometry>
      </collision>
      <visual name='wheel_4_visual'>
        <pose>0 0 0 0 -0 0</pose>
        <geometry>
          <mesh>
            <scale>1 1 1</scale>
            <uri>model://axioma_urdf/meshes/visual/llanta.stl</uri>
          </mesh>
        </geometry>
      </visual>
    </link>
  </model>
</sdf>
